Workbook

Sheet Carátula
B3: UNIVERSIDAD NACIONAL SANTIAGO ANTÚNEZ DE MAYOLO
B4: FACULTAD DE ECONOMÍA Y CONTABILIDAD
B5: ESCUELA PROFESIONAL DE CONTABILIDAD
B7: ACTIVIDAD PRÁCTICA II: MEDIDAS DE POSICIÓN
B8: Media aritmética, mediana y moda
B10: CURSO: ESTADÍSTICA APLICADA A LOS NEGOCIOS
B11: DOCENTE: Dra. ROBLES COLONIA SADITT ROCIO
B13: ALUMNOS:
B14: Castillo Perez Epifanio Jasdler
B15: Cordova Perez Ilda Maria
B16: Gonzáles Huaraz Jennifer
B17: Regalado Vilcapuma Xiomara
B19: Huaraz - 2026

Sheet Datos
B2: BASE DE DATOS: 40 clientes atendidos en una jornada
B4: Cliente | C4: Sexo | D4: Edad | E4: Comprobante | F4: Pago | G4: Productos | H4: Monto (S/) | I4: Tiempo (min) | J4: Satisfacción | K4: Reclamo
B5: 1 | C5: F | D5: 22 | E5: Boleta | F5: Yape | G5: 3 | H5: 85.5 | I5: 8 | J5: Satisfecho | K5: No
B6: 2 | C6: M | D6: 35 | E6: Factura | F6: Tarjeta | G6: 5 | H6: 240 | I6: 15 | J6: Muy satisfecho | K6: No
B7: 3 | C7: F | D7: 28 | E7: Boleta | F7: Efectivo | G7: 2 | H7: 55 | I7: 7 | J7: Regular | K7: No
B8: 4 | C8: M | D8: 42 | E8: Factura | F8: Yape | G8: 7 | H8: 315.8 | I8: 21 | J8: Satisfecho | K8: Si
B9: 5 | C9: F | D9: 31 | E9: Nota de venta | F9: Efectivo | G9: 4 | H9: 120.5 | I9: 12 | J9: Regular | K9: No
B10: 6 | C10: M | D10: 25 | E10: Boleta | F10: Transferencia | G10: 3 | H10: 98 | I10: 10 | J10: Satisfecho | K10: No
B11: 7 | C11: F | D11: 39 | E11: Factura | F11: Yape | G11: 8 | H11: 420 | I11: 25 | J11: Muy satisfecho | K11: No
B12: 8 | C12: M | D12: 23 | E12: Boleta | F12: Tarjeta | G12: 2 | H12: 75.5 | I12: 9 | J12: Satisfecho | K12: No
B13: 9 | C13: F | D13: 45 | E13: Factura | F13: Efectivo | G13: 6 | H13: 280 | I13: 18 | J13: Regular | K13: Si
B14: 10 | C14: M | D14: 29 | E14: Boleta | F14: Yape | G14: 4 | H14: 135 | I14: 11 | J14: Muy satisfecho | K14: No
B15: 11 | C15: F | D15: 34 | E15: Nota de venta | F15: Efectivo | G15: 3 | H15: 92 | I15: 10 | J15: Regular | K15: No
B16: 12 | C16: M | D16: 48 | E16: Factura | F16: Transferencia | G16: 9 | H16: 510 | I16: 30 | J16: Satisfecho | K16: Si
... B44: 40 | C44: M | D44: 30 | E44: Boleta | F44: Yape | G44: 4 | H44: 142 | I44: 12 | J44: Muy satisfecho | K44: No
B46: Nota: en el archivo original 6 montos (clientes 1, 4, 5, 8, 13 y 16) estaban guardados como TEXTO; aquí se convirtieron a número
B47: para que Excel los incluya en PROMEDIO y MEDIANA. Con el error, Excel habría ignorado esos 6 datos (promedio falso de S/ 210.50 con n = 34).

Sheet 1. Selección
B2: 1. IDENTIFICACIÓN DE LAS MEDIDAS DE POSICIÓN PERTINENTES
B4: Variable | C4: Tipo | D4: Escala | E4: Media | F4: Mediana | G4: Moda | H4: Justificación
B5: Sexo | C5: Cualitativa | D5: Nominal | E5: No | F5: No | G5: Sí | H5: Categorías sin orden ni valor numérico: solo se puede contar cuál se repite más.
B6: Edad | C6: Cuantitativa | D6: Razón | E6: Sí | F6: Sí | G6: Sí | H6: Valores numéricos con cero absoluto: se pueden sumar, ordenar y contar.
B7: Comprobante | C7: Cualitativa | D7: Nominal | E7: No | F7: No | G7: Sí | H7: Boleta/Factura/Nota de venta no tienen orden ni se pueden promediar.
B8: Pago | C8: Cualitativa | D8: Nominal | E8: No | F8: No | G8: Sí | H8: Yape/Efectivo/Tarjeta/Transferencia: solo frecuencia (moda).
B9: Productos | C9: Cuantitativa discreta | D9: Razón | E9: Sí | F9: Sí | G9: Sí | H9: Conteo de unidades: admite las tres medidas; la moda es muy informativa por ser discreta.
B10: Monto | C10: Cuantitativa continua | D10: Razón | E10: Sí | F10: Sí | G10: Sí* | H10: Admite las tres medidas. *Casi todos los montos son distintos: la moda es poco representativa.
B11: Tiempo | C11: Cuantitativa | D11: Razón | E11: Sí | F11: Sí | G11: Sí | H11: Minutos de atención: admite las tres medidas.
B12: Satisfacción | C12: Cualitativa | D12: Ordinal | E12: No | F12: Sí | G12: Sí | H12: Las categorías tienen orden (Regular < Satisfecho < Muy satisfecho): mediana y moda, pero no media.
B13: Reclamo | C13: Cualitativa | D13: Nominal | E13: No | F13: No | G13: Sí | H13: Sí/No: solo la moda.
B15: La variable Cliente es solo un código de identificación; no se le calcula ninguna medida.

Sheet 2. Cálculo manual
B2: 2. CÁLCULO MANUAL (datos originales ordenados de menor a mayor)
B4: Posición | C4: Edad | D4: Productos | E4: Monto (S/) | F4: Tiempo (min) | H4: 1. EDAD (años)
B5: 1 | C5: 21 | D5: 2 | E5: 55 | F5: 7 | H5: a) Media aritmética: x̄ = Σxi / n
B6: 2 | C6: 22 | D6: 2 | E6: 58 | F6: 7 | H6: Σxi = 22+35+28+42+31+25+39+23+45+29+34+48+26+37+30+41+33+24+36+27+44+32+21+38+29+43+35+22+40+26+47+31+24+39+27+45+33+28+42+30 = 1331
B7: 3 | C7: 22 | D7: 2 | E7: 60 | F7: 7 | H7: x̄ = 1331 / 40 = 33.275 ≈ 33.28 años
B8: 4 | C8: 23 | D8: 2 | E8: 65 | F8: 8 | H8: b) Mediana: n = 40 (par) → posiciones n/2 = 20 y n/2 + 1 = 21 de los datos ordenados
B9: 5 | C9: 24 | D9: 2 | E9: 68.5 | F9: 8 | H9: x(20) = 32 y x(21) = 33 → Me = (32 + 33) / 2 = 32.5 años
B10: 6 | C10: 24 | D10: 2 | E10: 72 | F10: 8 | H10: c) Moda: se cuenta cuántas veces se repite cada edad.
B11: 7 | C11: 25 | D11: 2 | E11: 75.5 | F11: 8 | H11: Edades que se repiten 2 veces (frecuencia máxima): 22, 24, 26, 27, 28, 29, 30, 31, 33, 35, 39, 42 y 45 (13 valores).
B12: 8 | C12: 26 | D12: 3 | E12: 85.5 | F12: 9 | H12: Las demás (21, 23, 25, 32, 34, 36, 37, 38, 40, 41, 43, 44, 47, 48) aparecen 1 vez.
B13: 9 | C13: 26 | D13: 3 | E13: 92 | F13: 9 | H13: → Distribución MULTIMODAL: ninguna edad destaca, por lo que en la práctica la edad no tiene una moda representativa.
B14: 10 | C14: 27 | D14: 3 | E14: 98 | F14: 10 | H14: d) Interpretación: el cliente típico es un adulto joven de unos 33 años. La mitad de los clientes tiene 32 años o menos y la otra mitad 33 o más.
B15: 11 | C15: 27 | D15: 3 | E15: 100 | F15: 10 | H15: Media (33.28) y mediana (32.5) son casi iguales → las edades están distribuidas de forma bastante simétrica (entre 21 y 48 años).
B16: 12 | C16: 28 | D16: 3 | E16: 105 | F16: 10 | H16: Media Edad = 33.275
B17: 13 | C17: 28 | D17: 3 | E17: 110 | F17: 10 | H17: Mediana Edad = 32.5
B18: 14 | C18: 29 | D18: 3 | E18: 115 | F18: 11
B19: 15 | C19: 29 | D19: 3 | E19: 120.5 | F19: 11 | H19: 2. NÚMERO DE PRODUCTOS
B20: 16 | C20: 30 | D20: 4 | E20: 125 | F20: 12 | H20: a) Media aritmética (con tabla de frecuencias): x̄ = Σ(xi·fi) / n
B21: 17 | C21: 30 | D21: 4 | E21: 135 | F21: 12 | H21: xi : 2 3 4 5 6 7 8 9
B22: 18 | C22: 31 | D22: 4 | E22: 135 | F22: 12 | H22: fi : 7 8 7 5 4 4 3 2
B23: 19 | C23: 31 | D23: 4 | E23: 142 | F23: 12 | H23: Σxi·fi = 2·7 + 3·8 + 4·7 + 5·5 + 6·4 + 7·4 + 8·3 + 9·2 = 14 + 24 + 28 + 25 + 24 + 28 + 24 + 18 = 185
B24: 20 | C24: 32 | D24: 4 | E24: 145.5 | F24: 13 | H24: x̄ = 185 / 40 = 4.625 productos
B25: 21 | C25: 33 | D25: 4 | E25: 150 | F25: 13 | H25: b) Mediana: posiciones 20 y 21. Frecuencias acumuladas Fi: 2→7, 3→15, 4→22 … ; las posiciones 20 y 21 caen en xi = 4
B26: 22 | C26: 33 | D26: 4 | E26: 155 | F26: 14 | H26: Me = (4 + 4) / 2 = 4 productos
B27: 23 | C27: 34 | D27: 5 | E27: 180 | F27: 14 | H27: c) Moda: el valor con mayor frecuencia es 3 (fi = 8) → Mo = 3 productos
B28: 24 | C28: 35 | D28: 5 | E28: 195 | F28: 15 | H28: d) ¿Qué medida describe mejor?: la MODA y la MEDIANA. Al ser una variable discreta, "4.625 productos" no puede ocurrir en la realidad;
B29: 25 | C29: 35 | D29: 5 | E29: 215 | F29: 15 | H29: la mediana (4) indica que la mitad de los clientes compró 4 productos o menos y la moda (3) es la cantidad comprada con más frecuencia.
B30: 26 | C30: 36 | D30: 5 | E30: 230 | F30: 16 | H30: La media está "jalada" hacia arriba por los pocos clientes que llevaron 8 o 9 productos.
... B33: 29 | C33: 39 | D33: 6 | E33: 275 | F33: 19 | H33: Moda Productos = 3
B34: 30 | C34: 39 | D34: 6 | E34: 280 | F34: 19
B35: 31 | C35: 40 | D35: 6 | E35: 290 | F35: 20 | H35: 3. MONTO DE COMPRA (S/)
B36: 32 | C36: 41 | D36: 7 | E36: 315.8 | F36: 21 | H36: a) Monto promedio: x̄ = Σxi / n
B37: 33 | C37: 42 | D37: 7 | E37: 325 | F37: 22 | H37: Σxi = 85.5+240+55+315.8+120.5+98+420+75.5+280+135+92+510+68.5+215+110+145.5+350+60+275+125+390+180+72+260+150+325+105+58+480+195
B38: 34 | C38: 42 | D38: 7 | E38: 335 | F38: 22 | H38: +290+135+115+410+65+230+155+100+335+142 = 7968.30
B39: 35 | C39: 43 | D39: 7 | E39: 350 | F39: 23 | H39: x̄ = 7968.30 / 40 = S/ 199.2075 ≈ S/ 199.21
B40: 36 | C40: 44 | D40: 8 | E40: 390 | F40: 25 | H40: b) Monto mediano: posiciones 20 y 21 → x(20) = 145.5 y x(21) = 150 → Me = (145.5 + 150) / 2 = S/ 147.75
B41: 37 | C41: 45 | D41: 8 | E41: 410 | F41: 26 | H41: c) Moda: el único monto que se repite es S/ 135 (clientes 10 y 32, fi = 2); los otros 38 montos aparecen una sola vez.
B42: 38 | C42: 45 | D42: 8 | E42: 420 | F42: 27 | H42: → Mo = S/ 135, pero es poco representativa: en una variable continua casi todos los valores son distintos.
B43: 39 | C43: 47 | D43: 9 | E43: 480 | F43: 29 | H43: d) Comparación: media (199.21) > mediana (147.75) por S/ 51.46. Unos pocos clientes con compras grandes (S/ 390 a S/ 510)
B44: 40 | C44: 48 | D44: 9 | E44: 510 | F44: 30 | H44: elevan el promedio → distribución con asimetría positiva (cola a la derecha). La mediana representa mejor la compra típica.
...

Sheet 3. Software (Excel)
B2: 3. MEDIDAS DE POSICIÓN OBTENIDAS CON EXCEL (fórmulas sobre la hoja Datos)
B4: Variable | C4: Media | D4: Mediana | E4: Moda (MODA.UNO) | F4: Frecuencia de la moda | G4: N.º de valores modales | H4: Fórmulas usadas (Excel en español)
B5: Edad (años) | C5: =AVERAGE(Datos!$D$5:$D$44) | D5: =MEDIAN(Datos!$D$5:$D$44) | E5: =_xlfn.MODE.SNGL(Datos!$D$5:$D$44) | F5: =COUNTIF(Datos!$D$5:$D$44,E5) | G5: =SUMPRODUCT((COUNTIF(Datos!$D$5:$D$44,Datos!$D$5:$D$44)=F5)/COUNTIF(Datos!$D$5:$D$44,Datos!$D$5:$D$44)) | H5: PROMEDIO(D5:D44) | MEDIANA(D5:D44) | MODA.UNO(D5:D44) | CONTAR.SI(D5:D44;moda)
B6: Número de productos | C6: =AVERAGE(Datos!$G$5:$G$44) | D6: =MEDIAN(Datos!$G$5:$G$44) | E6: =_xlfn.MODE.SNGL(Datos!$G$5:$G$44) | F6: =COUNTIF(Datos!$G$5:$G$44,E6) | G6: =SUMPRODUCT((COUNTIF(Datos!$G$5:$G$44,Datos!$G$5:$G$44)=F6)/COUNTIF(Datos!$G$5:$G$44,Datos!$G$5:$G$44)) | H6: PROMEDIO(G5:G44) | MEDIANA(G5:G44) | MODA.UNO(G5:G44) | CONTAR.SI(G5:G44;moda)
B7: Monto de compra (S/) | C7: =AVERAGE(Datos!$H$5:$H$44) | D7: =MEDIAN(Datos!$H$5:$H$44) | E7: =_xlfn.MODE.SNGL(Datos!$H$5:$H$44) | F7: =COUNTIF(Datos!$H$5:$H$44,E7) | G7: =SUMPRODUCT((COUNTIF(Datos!$H$5:$H$44,Datos!$H$5:$H$44)=F7)/COUNTIF(Datos!$H$5:$H$44,Datos!$H$5:$H$44)) | H7: PROMEDIO(H5:H44) | MEDIANA(H5:H44) | MODA.UNO(H5:H44) | CONTAR.SI(H5:H44;moda)
B8: Tiempo de atención (min) | C8: =AVERAGE(Datos!$I$5:$I$44) | D8: =MEDIAN(Datos!$I$5:$I$44) | E8: =_xlfn.MODE.SNGL(Datos!$I$5:$I$44) | F8: =COUNTIF(Datos!$I$5:$I$44,E8) | G8: =SUMPRODUCT((COUNTIF(Datos!$I$5:$I$44,Datos!$I$5:$I$44)=F8)/COUNTIF(Datos!$I$5:$I$44,Datos!$I$5:$I$44)) | H8: PROMEDIO(I5:I44) | MEDIANA(I5:I44) | MODA.UNO(I5:I44) | CONTAR.SI(I5:I44;moda)
B10: Lectura: si "N.º de valores modales" es mayor que 1, la variable es multimodal y Excel solo muestra la primera moda que encuentra.
B11: Edad: 13 valores empatan con frecuencia 2 (multimodal). Tiempo: 8, 10 y 12 empatan con frecuencia 4 (trimodal). Use =MODA.VARIOS() para verlos todos.
B13: Satisfacción (cualitativa ordinal)
B14: Categoría (en orden) | C14: fi | D14: Fi | E14: Posiciones
B15: Regular | C15: =COUNTIF(Datos!$J$5:$J$44,B15) | D15: =C15 | E15: ="1 – "&D15
B16: Satisfecho | C16: =COUNTIF(Datos!$J$5:$J$44,B16) | D16: =D15+C16 | E16: =D15+1&" – "&D16
B17: Muy satisfecho | C17: =COUNTIF(Datos!$J$5:$J$44,B17) | D17: =D16+C17 | E17: =D16+1&" – "&D17
B19: Moda | C19: =INDEX(B15:B17,MATCH(MAX(C15:C17),C15:C17,0))
B20: Mediana | C20: =IF(D15>=(D17+1)/2,B15,IF(D16>=(D17+1)/2,B16,B17))
B21: Mediana: primera categoría cuya Fi alcanza la posición central (n+1)/2 = 20.5.
B23: Evidencia: tome una captura de pantalla de esta hoja (y de la barra de fórmulas al seleccionar una celda) para adjuntarla al informe.

Sheet 4. Comparación
B2: 4. COMPARACIÓN: CÁLCULO MANUAL vs SOFTWARE
B4: Variable | C4: Medida | D4: Manual | E4: Software | F4: ¿Coinciden?
B5: Edad | C5: Media | D5: 33.275 | E5: ='3. Software (Excel)'!C5 | F5: =IF(ROUND(D5,4)=ROUND(E5,4),"Sí","No")
B6: Edad | C6: Mediana | D6: 32.5 | E6: ='3. Software (Excel)'!D5 | F6: =IF(ROUND(D6,4)=ROUND(E6,4),"Sí","No")
B7: Productos | C7: Moda | D7: 3 | E7: ='3. Software (Excel)'!E6 | F7: =IF(ROUND(D7,4)=ROUND(E7,4),"Sí","No")
B8: Monto | C8: Media | D8: 199.2075 | E8: ='3. Software (Excel)'!C7 | F8: =IF(ROUND(D8,4)=ROUND(E8,4),"Sí","No")
B9: Monto | C9: Mediana | D9: 147.75 | E9: ='3. Software (Excel)'!D7 | F9: =IF(ROUND(D9,4)=ROUND(E9,4),"Sí","No")
B10: Tiempo | C10: Media | D10: 14.975 | E10: ='3. Software (Excel)'!C8 | F10: =IF(ROUND(D10,4)=ROUND(E10,4),"Sí","No")
B11: Tiempo | C11: Mediana | D11: 13 | E11: ='3. Software (Excel)'!D8 | F11: =IF(ROUND(D11,4)=ROUND(E11,4),"Sí","No")
B13: Manual (azul) = resultados de la hoja "2. Cálculo manual". Software (verde) = enlazado a la hoja "3. Software (Excel)".
B14: Todos los resultados coinciden: el software usa las mismas definiciones (Σx/n, valor central, valor más frecuente); solo acelera el cálculo.
B15: Precaución: si los montos guardados como texto no se corrigen, Excel los ignora y el promedio sale S/ 210.50 (n = 34) en vez de S/ 199.21.

Sheet 5. Preguntas
B2: 5. PREGUNTAS DE ANÁLISIS E INTERPRETACIÓN
B4: 1. | C4: ¿Cuál es la edad promedio de los clientes? Interprete el resultado.
C5: Rpta: x̄ = 1331 / 40 = 33.28 años. El cliente "típico" de la empresa es un adulto joven de aproximadamente 33 años; el público objetivo son personas de 21 a 48 años.
B7: 2. | C7: ¿Cuál es la edad mediana? ¿Qué significa este valor en el grupo de clientes?
C8: Rpta: Me = 32.5 años. El 50% de los clientes tiene 32 años o menos y el otro 50% tiene 33 años o más. Al ser casi igual a la media, las edades son bastante simétricas.
B10: 3. | C10: ¿Cuál es el número de productos adquirido con mayor frecuencia?
C11: Rpta: Mo = 3 productos, comprado por 8 de los 40 clientes (20%).
B13: 4. | C13: ¿Cuál es el monto promedio de compra? Interprete el resultado en el contexto de la empresa.
C14: Rpta: x̄ = S/ 199.21. Si las ventas de la jornada (S/ 7,968.30) se repartieran por igual, cada cliente habría gastado S/ 199.21. Sirve para proyectar ingresos:
C15: p. ej., 100 clientes ≈ S/ 19,921. Pero ese valor está influido por pocas compras grandes.
B17: 5. | C17: ¿Cuál es la mediana del monto de compra? Interprete este resultado.
C18: Rpta: Me = S/ 147.75. La mitad de los clientes gastó S/ 147.75 o menos y la otra mitad gastó más. Es el monto que divide a los clientes en dos grupos de igual tamaño.
B20: 6. | C20: Compare la media y la mediana del monto de compra. ¿Son iguales o diferentes?
C21: Rpta: Son diferentes: media S/ 199.21 > mediana S/ 147.75 (diferencia S/ 51.46). Indica asimetría positiva: la mayoría compra montos bajos o medios
C22: y unos pocos clientes con compras altas elevan el promedio.
B24: 7. | C24: ¿Qué clientes o valores podrían estar influyendo en el monto promedio de compra?
C25: Rpta: Los montos más altos: cliente 12 (S/ 510), 29 (S/ 480), 7 (S/ 420), 34 (S/ 410), 21 (S/ 390) y 17 (S/ 350). Todos pidieron Factura, llevaron 7 a 9 productos
C26: y tuvieron tiempos de atención largos (22 a 30 min); probablemente son empresas o compras al por mayor.
B28: 8. | C28: ¿Cuál es el tiempo promedio de atención?
C29: Rpta: x̄ = 599 / 40 = 14.98 minutos (casi 15 minutos por cliente).
B31: 9. | C31: ¿Cuál es el tiempo mediano de atención?
C32: Rpta: Me = 13 minutos: la mitad de los clientes fue atendida en 13 minutos o menos.
B34: 10. | C34: ¿Cuál es el tiempo de atención más frecuente?
C35: Rpta: Hay tres modas: 8, 10 y 12 minutos (4 clientes cada uno). La distribución es trimodal.
B37: 11. | C37: Compare la media, mediana y moda del tiempo de atención. ¿Qué observa?
C38: Rpta: Moda (8–12) < Mediana (13) < Media (14.98). Las tres son distintas y la media es la mayor → asimetría positiva: la mayoría es atendida rápido
C39: y unos pocos casos largos (25–30 min, ligados a compras grandes) elevan el promedio. Para describir el tiempo típico es mejor la mediana.
B41: 12. | C41: ¿Cuál es el nivel de satisfacción más frecuente?
C42: Rpta: Mo = "Satisfecho" (18 clientes, 45%). La mediana también es "Satisfecho".
B44: 13. | C44: ¿Por qué la media aritmética no debe calcularse para variables como sexo, comprobante o medio de pago?
C45: Rpta: Porque son variables cualitativas nominales: sus valores son nombres o categorías, no cantidades. No se pueden sumar ni dividir ("Boleta + Factura" no tiene sentido).
C46: Si se les asignan códigos (1, 2, 3) estos son arbitrarios y su promedio no significa nada. Para ellas solo es válida la moda.
B48: 14. | C48: ¿Puede calcularse la moda para una variable cualitativa? Explique y presente un ejemplo de la base de datos.
C49: Rpta: Sí. La moda solo requiere contar frecuencias, por eso es la única medida de posición válida para variables nominales. Ejemplos:
C50: Medio de pago: Mo = Yape (13 clientes, 32.5%). Comprobante: Mo = Boleta (17 clientes, 42.5%). Reclamo: Mo = No (34 clientes, 85%).
C51: Sexo: F = 20 y M = 20 → distribución bimodal (no hay una sola moda).
B53: 15. | C53: ¿En qué situaciones la mediana puede ser más informativa que la media aritmética?
C54: Rpta: • Cuando hay valores extremos (atípicos) o la distribución es asimétrica, como el Monto y el Tiempo de esta base: la mediana no se deja arrastrar por ellos.
C55: • En variables ordinales (Satisfacción), donde la media no se puede calcular pero la mediana sí.
C56: • En variables discretas, donde la media puede dar un valor imposible (4.625 productos) y la mediana da un valor real (4).
...
